2025-09-25 09:54:06,188 - ERROR - Device:ZXRC21016024 | Employee:MUHAMMED ASHIK A(5017) | Error:HTTP Error 417: {"exception":"frappe.exceptions.ValidationError: Error processing checkin: (1136, \"Column count doesn't match value count at row 1\")","exc_type":"ValidationError","_exc_source":"sil (app)","exc":"[\"Traceback (most recent call last):\\n  File \\\"apps/sil/sil/test/biometric_to_erp.py\\\", line 31, in add_checkin\\n    return handle_employee_checkin(employee_id, full_name, checkin_time, checkin_date, device_id)\\n  File \\\"apps/sil/sil/test/biometric_to_erp.py\\\", line 66, in handle_employee_checkin\\n    frappe.db.sql(\\\"\\\"\\\"\\n  File \\\"apps/frappe/frappe/database/database.py\\\", line 229, in sql\\n    self._cursor.execute(query, values)\\n  File \\\"env/lib/python3.10/site-packages/pymysql/cursors.py\\\", line 153, in execute\\n    result = self._query(query)\\n  File \\\"env/lib/python3.10/site-packages/pymysql/cursors.py\\\", line 322, in _query\\n    conn.query(q)\\n  File \\\"env/lib/python3.10/site-packages/pymysql/connections.py\\\", line 563, in query\\n    self._affected_rows = self._read_query_result(unbuffered=unbuffered)\\n  File \\\"env/lib/python3.10/site-packages/pymysql/connections.py\\\", line 825, in _read_query_result\\n    result.read()\\n  File \\\"env/lib/python3.10/site-packages/pymysql/connections.py\\\", line 1199, in read\\n    first_packet = self.connection._read_packet()\\n  File \\\"env/lib/python3.10/site-packages/pymysql/connections.py\\\", line 775, in _read_packet\\n    packet.raise_for_error()\\n  File \\\"env/lib/python3.10/site-packages/pymysql/protocol.py\\\", line 219, in raise_for_error\\n    err.raise_mysql_exception(self._data)\\n  File \\\"env/lib/python3.10/site-packages/pymysql/err.py\\\", line 150, in raise_mysql_exception\\n    raise errorclass(errno, errval)\\npymysql.err.OperationalError: (1136, \\\"Column count doesn't match value count at row 1\\\")\\n\\nDuring handling of the above exception, another exception occurred:\\n\\nTraceback (most recent call last):\\n  File \\\"apps/frappe/frappe/app.py\\\", line 114, in application\\n    response = frappe.api.handle(request)\\n  File \\\"apps/frappe/frappe/api/__init__.py\\\", line 49, in handle\\n    data = endpoint(**arguments)\\n  File \\\"apps/frappe/frappe/api/v1.py\\\", line 36, in handle_rpc_call\\n    return frappe.handler.handle()\\n  File \\\"apps/frappe/frappe/handler.py\\\", line 49, in handle\\n    data = execute_cmd(cmd)\\n  File \\\"apps/frappe/frappe/handler.py\\\", line 85, in execute_cmd\\n    return frappe.call(method, **frappe.form_dict)\\n  File \\\"apps/frappe/frappe/__init__.py\\\", line 1725, in call\\n    return fn(*args, **newargs)\\n  File \\\"apps/frappe/frappe/utils/typing_validations.py\\\", line 31, in wrapper\\n    return func(*args, **kwargs)\\n  File \\\"apps/sil/sil/test/biometric_to_erp.py\\\", line 37, in add_checkin\\n    frappe.throw(_(\\\"Error processing checkin: {0}\\\").format(str(e)))\\n  File \\\"apps/frappe/frappe/__init__.py\\\", line 602, in throw\\n    msgprint(\\n  File \\\"apps/frappe/frappe/__init__.py\\\", line 567, in msgprint\\n    _raise_exception()\\n  File \\\"apps/frappe/frappe/__init__.py\\\", line 518, in _raise_exception\\n    raise exc\\nfrappe.exceptions.ValidationError: Error processing checkin: (1136, \\\"Column count doesn't match value count at row 1\\\")\\n\"]","_server_messages":"[\"{\\\"message\\\": \\\"Error processing checkin: (1136, \\\\\\\"Column count doesn't match value count at row 1\\\\\\\")\\\", \\\"title\\\": \\\"Message\\\", \\\"indicator\\\": \\\"red\\\", \\\"raise_exception\\\": 1, \\\"__frappe_exc_id\\\": \\\"95f9884e3ef6650dc9df0e6c6aca61d751b672c06ea58cc9939fc6fe\\\"}\"]"} | Type:HTTP_ERROR | Status:ERROR
2025-09-25 09:54:20,648 - ERROR - Device:ZXRC21016024 | Employee:ADHWAITH KRISHNAN J.R(5022) | Error:HTTP Error 417: {"exception":"frappe.exceptions.ValidationError: Error processing checkin: (1136, \"Column count doesn't match value count at row 1\")","exc_type":"ValidationError","_exc_source":"sil (app)","exc":"[\"Traceback (most recent call last):\\n  File \\\"apps/sil/sil/test/biometric_to_erp.py\\\", line 31, in add_checkin\\n    return handle_employee_checkin(employee_id, full_name, checkin_time, checkin_date, device_id)\\n  File \\\"apps/sil/sil/test/biometric_to_erp.py\\\", line 66, in handle_employee_checkin\\n    frappe.db.sql(\\\"\\\"\\\"\\n  File \\\"apps/frappe/frappe/database/database.py\\\", line 229, in sql\\n    self._cursor.execute(query, values)\\n  File \\\"env/lib/python3.10/site-packages/pymysql/cursors.py\\\", line 153, in execute\\n    result = self._query(query)\\n  File \\\"env/lib/python3.10/site-packages/pymysql/cursors.py\\\", line 322, in _query\\n    conn.query(q)\\n  File \\\"env/lib/python3.10/site-packages/pymysql/connections.py\\\", line 563, in query\\n    self._affected_rows = self._read_query_result(unbuffered=unbuffered)\\n  File \\\"env/lib/python3.10/site-packages/pymysql/connections.py\\\", line 825, in _read_query_result\\n    result.read()\\n  File \\\"env/lib/python3.10/site-packages/pymysql/connections.py\\\", line 1199, in read\\n    first_packet = self.connection._read_packet()\\n  File \\\"env/lib/python3.10/site-packages/pymysql/connections.py\\\", line 775, in _read_packet\\n    packet.raise_for_error()\\n  File \\\"env/lib/python3.10/site-packages/pymysql/protocol.py\\\", line 219, in raise_for_error\\n    err.raise_mysql_exception(self._data)\\n  File \\\"env/lib/python3.10/site-packages/pymysql/err.py\\\", line 150, in raise_mysql_exception\\n    raise errorclass(errno, errval)\\npymysql.err.OperationalError: (1136, \\\"Column count doesn't match value count at row 1\\\")\\n\\nDuring handling of the above exception, another exception occurred:\\n\\nTraceback (most recent call last):\\n  File \\\"apps/frappe/frappe/app.py\\\", line 114, in application\\n    response = frappe.api.handle(request)\\n  File \\\"apps/frappe/frappe/api/__init__.py\\\", line 49, in handle\\n    data = endpoint(**arguments)\\n  File \\\"apps/frappe/frappe/api/v1.py\\\", line 36, in handle_rpc_call\\n    return frappe.handler.handle()\\n  File \\\"apps/frappe/frappe/handler.py\\\", line 49, in handle\\n    data = execute_cmd(cmd)\\n  File \\\"apps/frappe/frappe/handler.py\\\", line 85, in execute_cmd\\n    return frappe.call(method, **frappe.form_dict)\\n  File \\\"apps/frappe/frappe/__init__.py\\\", line 1725, in call\\n    return fn(*args, **newargs)\\n  File \\\"apps/frappe/frappe/utils/typing_validations.py\\\", line 31, in wrapper\\n    return func(*args, **kwargs)\\n  File \\\"apps/sil/sil/test/biometric_to_erp.py\\\", line 37, in add_checkin\\n    frappe.throw(_(\\\"Error processing checkin: {0}\\\").format(str(e)))\\n  File \\\"apps/frappe/frappe/__init__.py\\\", line 602, in throw\\n    msgprint(\\n  File \\\"apps/frappe/frappe/__init__.py\\\", line 567, in msgprint\\n    _raise_exception()\\n  File \\\"apps/frappe/frappe/__init__.py\\\", line 518, in _raise_exception\\n    raise exc\\nfrappe.exceptions.ValidationError: Error processing checkin: (1136, \\\"Column count doesn't match value count at row 1\\\")\\n\"]","_server_messages":"[\"{\\\"message\\\": \\\"Error processing checkin: (1136, \\\\\\\"Column count doesn't match value count at row 1\\\\\\\")\\\", \\\"title\\\": \\\"Message\\\", \\\"indicator\\\": \\\"red\\\", \\\"raise_exception\\\": 1, \\\"__frappe_exc_id\\\": \\\"f32c327ca101fb9210334d9b0a613f6bdc94fe6f374bfee21a1e6f0d\\\"}\"]"} | Type:HTTP_ERROR | Status:ERROR
